<?xml version="1.0" encoding="UTF-8"?>
<!-- Generated by org.testng.reporters.JUnitXMLReporter -->
<testsuite hostname="XWJPMDD035" ignored="0" name="Default test" tests="8" failures="8" timestamp="14 Jun 2017 13:09:21 GMT" time="1.205" errors="0">
  <testcase name="@BeforeClass InitTest" time="0.0" classname="app.psc.testcases.accountverification.accountverification_existingusr">
    <failure type="java.lang.NullPointerException">
      <![CDATA[java.lang.NullPointerException
	at lib.Reporter.initializeModule(Reporter.java:74)
	at app.psc.testcases.accountverification.accountverification_existingusr.InitTest(accountverification_existingusr.java:37)
	at sun.reflect.NativeMethodAccessorImpl.invoke0(Native Method)
	at sun.reflect.NativeMethodAccessorImpl.invoke(NativeMethodAccessorImpl.java:62)
	at sun.reflect.DelegatingMethodAccessorImpl.invoke(DelegatingMethodAccessorImpl.java:43)
	at java.lang.reflect.Method.invoke(Method.java:498)
	at org.testng.internal.MethodInvocationHelper.invokeMethod(MethodInvocationHelper.java:104)
	at org.testng.internal.Invoker.invokeConfigurationMethod(Invoker.java:515)
	at org.testng.internal.Invoker.invokeConfigurations(Invoker.java:217)
	at org.testng.internal.Invoker.invokeConfigurations(Invoker.java:144)
	at org.testng.internal.TestMethodWorker.invokeBeforeClassMethods(TestMethodWorker.java:169)
	at org.testng.internal.TestMethodWorker.run(TestMethodWorker.java:108)
	at org.testng.TestRunner.privateRun(TestRunner.java:756)
	at org.testng.TestRunner.run(TestRunner.java:610)
	at org.testng.SuiteRunner.runTest(SuiteRunner.java:387)
	at org.testng.SuiteRunner.runSequentially(SuiteRunner.java:382)
	at org.testng.SuiteRunner.privateRun(SuiteRunner.java:340)
	at org.testng.SuiteRunner.run(SuiteRunner.java:289)
	at org.testng.SuiteRunnerWorker.runSuite(SuiteRunnerWorker.java:52)
	at org.testng.SuiteRunnerWorker.run(SuiteRunnerWorker.java:86)
	at org.testng.TestNG.runSuitesSequentially(TestNG.java:1293)
	at org.testng.TestNG.runSuitesLocally(TestNG.java:1218)
	at org.testng.TestNG.runSuites(TestNG.java:1133)
	at org.testng.TestNG.run(TestNG.java:1104)
	at org.testng.remote.AbstractRemoteTestNG.run(AbstractRemoteTestNG.java:132)
	at org.testng.remote.RemoteTestNG.initAndRun(RemoteTestNG.java:236)
	at org.testng.remote.RemoteTestNG.main(RemoteTestNG.java:81)
]]>
    </failure>
  </testcase> <!-- @BeforeClass InitTest -->
  <testcase name="TC004_01_Verify_Changepasword_When_Password_Expired_Negative_Scenario" time="0.951" classname="app.psc.testcases.accountverification.accountverification_existingusr">
    <failure type="org.testng.internal.reflect.MethodMatcherException" message="
Data provider mismatch
Method: TC004_01_Verify_Changepasword_When_Password_Expired_Negative_Scenario([Parameter{index=0, type=int, declaredAnnotations=[]}, Parameter{index=1, type=java.util.Map, declaredAnnotations=[]}])
Arguments: []">
      <![CDATA[org.testng.internal.reflect.MethodMatcherException: 
Data provider mismatch
Method: TC004_01_Verify_Changepasword_When_Password_Expired_Negative_Scenario([Parameter{index=0, type=int, declaredAnnotations=[]}, Parameter{index=1, type=java.util.Map, declaredAnnotations=[]}])
Arguments: []
	at org.testng.internal.reflect.DataProviderMethodMatcher.getConformingArguments(DataProviderMethodMatcher.java:52)
	at org.testng.internal.Invoker.injectParameters(Invoker.java:1278)
	at org.testng.internal.Invoker.invokeTestMethods(Invoker.java:1171)
	at org.testng.internal.TestMethodWorker.invokeTestMethods(TestMethodWorker.java:129)
	at org.testng.internal.TestMethodWorker.run(TestMethodWorker.java:112)
	at org.testng.TestRunner.privateRun(TestRunner.java:756)
	at org.testng.TestRunner.run(TestRunner.java:610)
	at org.testng.SuiteRunner.runTest(SuiteRunner.java:387)
	at org.testng.SuiteRunner.runSequentially(SuiteRunner.java:382)
	at org.testng.SuiteRunner.privateRun(SuiteRunner.java:340)
	at org.testng.SuiteRunner.run(SuiteRunner.java:289)
	at org.testng.SuiteRunnerWorker.runSuite(SuiteRunnerWorker.java:52)
	at org.testng.SuiteRunnerWorker.run(SuiteRunnerWorker.java:86)
	at org.testng.TestNG.runSuitesSequentially(TestNG.java:1293)
	at org.testng.TestNG.runSuitesLocally(TestNG.java:1218)
	at org.testng.TestNG.runSuites(TestNG.java:1133)
	at org.testng.TestNG.run(TestNG.java:1104)
	at org.testng.remote.AbstractRemoteTestNG.run(AbstractRemoteTestNG.java:132)
	at org.testng.remote.RemoteTestNG.initAndRun(RemoteTestNG.java:236)
	at org.testng.remote.RemoteTestNG.main(RemoteTestNG.java:81)
]]>
    </failure>
  </testcase> <!-- TC004_01_Verify_Changepasword_When_Password_Expired_Negative_Scenario -->
  <testcase name="TC004_02_Verify_Changepasword_When_Password_Expired_Positive_Flow" time="0.015" classname="app.psc.testcases.accountverification.accountverification_existingusr">
    <failure type="org.testng.internal.reflect.MethodMatcherException" message="
Data provider mismatch
Method: TC004_02_Verify_Changepasword_When_Password_Expired_Positive_Flow([Parameter{index=0, type=int, declaredAnnotations=[]}, Parameter{index=1, type=java.util.Map, declaredAnnotations=[]}])
Arguments: []">
      <![CDATA[org.testng.internal.reflect.MethodMatcherException: 
Data provider mismatch
Method: TC004_02_Verify_Changepasword_When_Password_Expired_Positive_Flow([Parameter{index=0, type=int, declaredAnnotations=[]}, Parameter{index=1, type=java.util.Map, declaredAnnotations=[]}])
Arguments: []
	at org.testng.internal.reflect.DataProviderMethodMatcher.getConformingArguments(DataProviderMethodMatcher.java:52)
	at org.testng.internal.Invoker.injectParameters(Invoker.java:1278)
	at org.testng.internal.Invoker.invokeTestMethods(Invoker.java:1171)
	at org.testng.internal.TestMethodWorker.invokeTestMethods(TestMethodWorker.java:129)
	at org.testng.internal.TestMethodWorker.run(TestMethodWorker.java:112)
	at org.testng.TestRunner.privateRun(TestRunner.java:756)
	at org.testng.TestRunner.run(TestRunner.java:610)
	at org.testng.SuiteRunner.runTest(SuiteRunner.java:387)
	at org.testng.SuiteRunner.runSequentially(SuiteRunner.java:382)
	at org.testng.SuiteRunner.privateRun(SuiteRunner.java:340)
	at org.testng.SuiteRunner.run(SuiteRunner.java:289)
	at org.testng.SuiteRunnerWorker.runSuite(SuiteRunnerWorker.java:52)
	at org.testng.SuiteRunnerWorker.run(SuiteRunnerWorker.java:86)
	at org.testng.TestNG.runSuitesSequentially(TestNG.java:1293)
	at org.testng.TestNG.runSuitesLocally(TestNG.java:1218)
	at org.testng.TestNG.runSuites(TestNG.java:1133)
	at org.testng.TestNG.run(TestNG.java:1104)
	at org.testng.remote.AbstractRemoteTestNG.run(AbstractRemoteTestNG.java:132)
	at org.testng.remote.RemoteTestNG.initAndRun(RemoteTestNG.java:236)
	at org.testng.remote.RemoteTestNG.main(RemoteTestNG.java:81)
]]>
    </failure>
  </testcase> <!-- TC004_02_Verify_Changepasword_When_Password_Expired_Positive_Flow -->
  <testcase name="TC005_01_Verify_PSC_Users_Are_Unbale_To_Reuse_Last_Ten_Passwords" time="0.0" classname="app.psc.testcases.accountverification.accountverification_existingusr">
    <failure type="org.testng.internal.reflect.MethodMatcherException" message="
Data provider mismatch
Method: TC005_01_Verify_PSC_Users_Are_Unbale_To_Reuse_Last_Ten_Passwords([Parameter{index=0, type=int, declaredAnnotations=[]}, Parameter{index=1, type=java.util.Map, declaredAnnotations=[]}])
Arguments: []">
      <![CDATA[org.testng.internal.reflect.MethodMatcherException: 
Data provider mismatch
Method: TC005_01_Verify_PSC_Users_Are_Unbale_To_Reuse_Last_Ten_Passwords([Parameter{index=0, type=int, declaredAnnotations=[]}, Parameter{index=1, type=java.util.Map, declaredAnnotations=[]}])
Arguments: []
	at org.testng.internal.reflect.DataProviderMethodMatcher.getConformingArguments(DataProviderMethodMatcher.java:52)
	at org.testng.internal.Invoker.injectParameters(Invoker.java:1278)
	at org.testng.internal.Invoker.invokeTestMethods(Invoker.java:1171)
	at org.testng.internal.TestMethodWorker.invokeTestMethods(TestMethodWorker.java:129)
	at org.testng.internal.TestMethodWorker.run(TestMethodWorker.java:112)
	at org.testng.TestRunner.privateRun(TestRunner.java:756)
	at org.testng.TestRunner.run(TestRunner.java:610)
	at org.testng.SuiteRunner.runTest(SuiteRunner.java:387)
	at org.testng.SuiteRunner.runSequentially(SuiteRunner.java:382)
	at org.testng.SuiteRunner.privateRun(SuiteRunner.java:340)
	at org.testng.SuiteRunner.run(SuiteRunner.java:289)
	at org.testng.SuiteRunnerWorker.runSuite(SuiteRunnerWorker.java:52)
	at org.testng.SuiteRunnerWorker.run(SuiteRunnerWorker.java:86)
	at org.testng.TestNG.runSuitesSequentially(TestNG.java:1293)
	at org.testng.TestNG.runSuitesLocally(TestNG.java:1218)
	at org.testng.TestNG.runSuites(TestNG.java:1133)
	at org.testng.TestNG.run(TestNG.java:1104)
	at org.testng.remote.AbstractRemoteTestNG.run(AbstractRemoteTestNG.java:132)
	at org.testng.remote.RemoteTestNG.initAndRun(RemoteTestNG.java:236)
	at org.testng.remote.RemoteTestNG.main(RemoteTestNG.java:81)
]]>
    </failure>
  </testcase> <!-- TC005_01_Verify_PSC_Users_Are_Unbale_To_Reuse_Last_Ten_Passwords -->
  <testcase name="TC006_01_Verify_Display_Of_Compliance_On_HomePage" time="0.031" classname="app.psc.testcases.accountverification.accountverification_existingusr">
    <failure type="org.testng.internal.reflect.MethodMatcherException" message="
Data provider mismatch
Method: TC006_01_Verify_Display_Of_Compliance_On_HomePage([Parameter{index=0, type=int, declaredAnnotations=[]}, Parameter{index=1, type=java.util.Map, declaredAnnotations=[]}])
Arguments: []">
      <![CDATA[org.testng.internal.reflect.MethodMatcherException: 
Data provider mismatch
Method: TC006_01_Verify_Display_Of_Compliance_On_HomePage([Parameter{index=0, type=int, declaredAnnotations=[]}, Parameter{index=1, type=java.util.Map, declaredAnnotations=[]}])
Arguments: []
	at org.testng.internal.reflect.DataProviderMethodMatcher.getConformingArguments(DataProviderMethodMatcher.java:52)
	at org.testng.internal.Invoker.injectParameters(Invoker.java:1278)
	at org.testng.internal.Invoker.invokeTestMethods(Invoker.java:1171)
	at org.testng.internal.TestMethodWorker.invokeTestMethods(TestMethodWorker.java:129)
	at org.testng.internal.TestMethodWorker.run(TestMethodWorker.java:112)
	at org.testng.TestRunner.privateRun(TestRunner.java:756)
	at org.testng.TestRunner.run(TestRunner.java:610)
	at org.testng.SuiteRunner.runTest(SuiteRunner.java:387)
	at org.testng.SuiteRunner.runSequentially(SuiteRunner.java:382)
	at org.testng.SuiteRunner.privateRun(SuiteRunner.java:340)
	at org.testng.SuiteRunner.run(SuiteRunner.java:289)
	at org.testng.SuiteRunnerWorker.runSuite(SuiteRunnerWorker.java:52)
	at org.testng.SuiteRunnerWorker.run(SuiteRunnerWorker.java:86)
	at org.testng.TestNG.runSuitesSequentially(TestNG.java:1293)
	at org.testng.TestNG.runSuitesLocally(TestNG.java:1218)
	at org.testng.TestNG.runSuites(TestNG.java:1133)
	at org.testng.TestNG.run(TestNG.java:1104)
	at org.testng.remote.AbstractRemoteTestNG.run(AbstractRemoteTestNG.java:132)
	at org.testng.remote.RemoteTestNG.initAndRun(RemoteTestNG.java:236)
	at org.testng.remote.RemoteTestNG.main(RemoteTestNG.java:81)
]]>
    </failure>
  </testcase> <!-- TC006_01_Verify_Display_Of_Compliance_On_HomePage -->
  <testcase name="TC006_01_Verify_Display_Of_Notification_On_HomePage" time="0.016" classname="app.psc.testcases.accountverification.accountverification_existingusr">
    <failure type="org.testng.internal.reflect.MethodMatcherException" message="
Data provider mismatch
Method: TC006_01_Verify_Display_Of_Notification_On_HomePage([Parameter{index=0, type=int, declaredAnnotations=[]}, Parameter{index=1, type=java.util.Map, declaredAnnotations=[]}])
Arguments: []">
      <![CDATA[org.testng.internal.reflect.MethodMatcherException: 
Data provider mismatch
Method: TC006_01_Verify_Display_Of_Notification_On_HomePage([Parameter{index=0, type=int, declaredAnnotations=[]}, Parameter{index=1, type=java.util.Map, declaredAnnotations=[]}])
Arguments: []
	at org.testng.internal.reflect.DataProviderMethodMatcher.getConformingArguments(DataProviderMethodMatcher.java:52)
	at org.testng.internal.Invoker.injectParameters(Invoker.java:1278)
	at org.testng.internal.Invoker.invokeTestMethods(Invoker.java:1171)
	at org.testng.internal.TestMethodWorker.invokeTestMethods(TestMethodWorker.java:129)
	at org.testng.internal.TestMethodWorker.run(TestMethodWorker.java:112)
	at org.testng.TestRunner.privateRun(TestRunner.java:756)
	at org.testng.TestRunner.run(TestRunner.java:610)
	at org.testng.SuiteRunner.runTest(SuiteRunner.java:387)
	at org.testng.SuiteRunner.runSequentially(SuiteRunner.java:382)
	at org.testng.SuiteRunner.privateRun(SuiteRunner.java:340)
	at org.testng.SuiteRunner.run(SuiteRunner.java:289)
	at org.testng.SuiteRunnerWorker.runSuite(SuiteRunnerWorker.java:52)
	at org.testng.SuiteRunnerWorker.run(SuiteRunnerWorker.java:86)
	at org.testng.TestNG.runSuitesSequentially(TestNG.java:1293)
	at org.testng.TestNG.runSuitesLocally(TestNG.java:1218)
	at org.testng.TestNG.runSuites(TestNG.java:1133)
	at org.testng.TestNG.run(TestNG.java:1104)
	at org.testng.remote.AbstractRemoteTestNG.run(AbstractRemoteTestNG.java:132)
	at org.testng.remote.RemoteTestNG.initAndRun(RemoteTestNG.java:236)
	at org.testng.remote.RemoteTestNG.main(RemoteTestNG.java:81)
]]>
    </failure>
  </testcase> <!-- TC006_01_Verify_Display_Of_Notification_On_HomePage -->
  <testcase name="TC009_01_Verify_Multifactoring" time="0.0" classname="app.psc.testcases.accountverification.accountverification_existingusr">
    <failure type="org.testng.internal.reflect.MethodMatcherException" message="
Data provider mismatch
Method: TC009_01_Verify_Multifactoring([Parameter{index=0, type=int, declaredAnnotations=[]}, Parameter{index=1, type=java.util.Map, declaredAnnotations=[]}])
Arguments: []">
      <![CDATA[org.testng.internal.reflect.MethodMatcherException: 
Data provider mismatch
Method: TC009_01_Verify_Multifactoring([Parameter{index=0, type=int, declaredAnnotations=[]}, Parameter{index=1, type=java.util.Map, declaredAnnotations=[]}])
Arguments: []
	at org.testng.internal.reflect.DataProviderMethodMatcher.getConformingArguments(DataProviderMethodMatcher.java:52)
	at org.testng.internal.Invoker.injectParameters(Invoker.java:1278)
	at org.testng.internal.Invoker.invokeTestMethods(Invoker.java:1171)
	at org.testng.internal.TestMethodWorker.invokeTestMethods(TestMethodWorker.java:129)
	at org.testng.internal.TestMethodWorker.run(TestMethodWorker.java:112)
	at org.testng.TestRunner.privateRun(TestRunner.java:756)
	at org.testng.TestRunner.run(TestRunner.java:610)
	at org.testng.SuiteRunner.runTest(SuiteRunner.java:387)
	at org.testng.SuiteRunner.runSequentially(SuiteRunner.java:382)
	at org.testng.SuiteRunner.privateRun(SuiteRunner.java:340)
	at org.testng.SuiteRunner.run(SuiteRunner.java:289)
	at org.testng.SuiteRunnerWorker.runSuite(SuiteRunnerWorker.java:52)
	at org.testng.SuiteRunnerWorker.run(SuiteRunnerWorker.java:86)
	at org.testng.TestNG.runSuitesSequentially(TestNG.java:1293)
	at org.testng.TestNG.runSuitesLocally(TestNG.java:1218)
	at org.testng.TestNG.runSuites(TestNG.java:1133)
	at org.testng.TestNG.run(TestNG.java:1104)
	at org.testng.remote.AbstractRemoteTestNG.run(AbstractRemoteTestNG.java:132)
	at org.testng.remote.RemoteTestNG.initAndRun(RemoteTestNG.java:236)
	at org.testng.remote.RemoteTestNG.main(RemoteTestNG.java:81)
]]>
    </failure>
  </testcase> <!-- TC009_01_Verify_Multifactoring -->
  <testcase name="TC018_Security_Question_Validation_Existing_User" time="0.0" classname="app.psc.testcases.accountverification.accountverification_existingusr">
    <failure type="org.testng.internal.reflect.MethodMatcherException" message="
Data provider mismatch
Method: TC018_Security_Question_Validation_Existing_User([Parameter{index=0, type=int, declaredAnnotations=[]}, Parameter{index=1, type=java.util.Map, declaredAnnotations=[]}])
Arguments: []">
      <![CDATA[org.testng.internal.reflect.MethodMatcherException: 
Data provider mismatch
Method: TC018_Security_Question_Validation_Existing_User([Parameter{index=0, type=int, declaredAnnotations=[]}, Parameter{index=1, type=java.util.Map, declaredAnnotations=[]}])
Arguments: []
	at org.testng.internal.reflect.DataProviderMethodMatcher.getConformingArguments(DataProviderMethodMatcher.java:52)
	at org.testng.internal.Invoker.injectParameters(Invoker.java:1278)
	at org.testng.internal.Invoker.invokeTestMethods(Invoker.java:1171)
	at org.testng.internal.TestMethodWorker.invokeTestMethods(TestMethodWorker.java:129)
	at org.testng.internal.TestMethodWorker.run(TestMethodWorker.java:112)
	at org.testng.TestRunner.privateRun(TestRunner.java:756)
	at org.testng.TestRunner.run(TestRunner.java:610)
	at org.testng.SuiteRunner.runTest(SuiteRunner.java:387)
	at org.testng.SuiteRunner.runSequentially(SuiteRunner.java:382)
	at org.testng.SuiteRunner.privateRun(SuiteRunner.java:340)
	at org.testng.SuiteRunner.run(SuiteRunner.java:289)
	at org.testng.SuiteRunnerWorker.runSuite(SuiteRunnerWorker.java:52)
	at org.testng.SuiteRunnerWorker.run(SuiteRunnerWorker.java:86)
	at org.testng.TestNG.runSuitesSequentially(TestNG.java:1293)
	at org.testng.TestNG.runSuitesLocally(TestNG.java:1218)
	at org.testng.TestNG.runSuites(TestNG.java:1133)
	at org.testng.TestNG.run(TestNG.java:1104)
	at org.testng.remote.AbstractRemoteTestNG.run(AbstractRemoteTestNG.java:132)
	at org.testng.remote.RemoteTestNG.initAndRun(RemoteTestNG.java:236)
	at org.testng.remote.RemoteTestNG.main(RemoteTestNG.java:81)
]]>
    </failure>
  </testcase> <!-- TC018_Security_Question_Validation_Existing_User -->
  <testcase name="TC019_Verify_Default_Plan_Prompting" time="0.016" classname="app.psc.testcases.accountverification.accountverification_existingusr">
    <failure type="org.testng.internal.reflect.MethodMatcherException" message="
Data provider mismatch
Method: TC019_Verify_Default_Plan_Prompting([Parameter{index=0, type=int, declaredAnnotations=[]}, Parameter{index=1, type=java.util.Map, declaredAnnotations=[]}])
Arguments: []">
      <![CDATA[org.testng.internal.reflect.MethodMatcherException: 
Data provider mismatch
Method: TC019_Verify_Default_Plan_Prompting([Parameter{index=0, type=int, declaredAnnotations=[]}, Parameter{index=1, type=java.util.Map, declaredAnnotations=[]}])
Arguments: []
	at org.testng.internal.reflect.DataProviderMethodMatcher.getConformingArguments(DataProviderMethodMatcher.java:52)
	at org.testng.internal.Invoker.injectParameters(Invoker.java:1278)
	at org.testng.internal.Invoker.invokeTestMethods(Invoker.java:1171)
	at org.testng.internal.TestMethodWorker.invokeTestMethods(TestMethodWorker.java:129)
	at org.testng.internal.TestMethodWorker.run(TestMethodWorker.java:112)
	at org.testng.TestRunner.privateRun(TestRunner.java:756)
	at org.testng.TestRunner.run(TestRunner.java:610)
	at org.testng.SuiteRunner.runTest(SuiteRunner.java:387)
	at org.testng.SuiteRunner.runSequentially(SuiteRunner.java:382)
	at org.testng.SuiteRunner.privateRun(SuiteRunner.java:340)
	at org.testng.SuiteRunner.run(SuiteRunner.java:289)
	at org.testng.SuiteRunnerWorker.runSuite(SuiteRunnerWorker.java:52)
	at org.testng.SuiteRunnerWorker.run(SuiteRunnerWorker.java:86)
	at org.testng.TestNG.runSuitesSequentially(TestNG.java:1293)
	at org.testng.TestNG.runSuitesLocally(TestNG.java:1218)
	at org.testng.TestNG.runSuites(TestNG.java:1133)
	at org.testng.TestNG.run(TestNG.java:1104)
	at org.testng.remote.AbstractRemoteTestNG.run(AbstractRemoteTestNG.java:132)
	at org.testng.remote.RemoteTestNG.initAndRun(RemoteTestNG.java:236)
	at org.testng.remote.RemoteTestNG.main(RemoteTestNG.java:81)
]]>
    </failure>
  </testcase> <!-- TC019_Verify_Default_Plan_Prompting -->
</testsuite> <!-- Default test -->
